<?xml version="1.0" encoding="utf-8"?>
<!-- =================================================================================== -->
<!-- |    This document was autogenerated by xacro from myrobot.xacro                  | -->
<!-- |    EDITING THIS FILE BY HAND IS NOT RECOMMENDED                                 | -->
<!-- =================================================================================== -->
<robot name="robot" xmlns:xacro="http://www.ros.org/wiki/xacro">
  <gazebo>
    <plugin filename="libgazebo_ros_diff_drive.so" name="differential_drive_controller">
      <legacyMode>false</legacyMode>
      <alwaysOn>true</alwaysOn>
      <updateRate>20</updateRate>
      <leftJoint>left_wheel_hinge</leftJoint>
      <rightJoint>right_wheel_hinge</rightJoint>
      <wheelSeparation>0.4</wheelSeparation>
      <wheelDiameter>0.1</wheelDiameter>
      <torque>20</torque>
      <commandTopic>cmd_vel</commandTopic>
      <odometryTopic>odom</odometryTopic>
      <odometryFrame>odom</odometryFrame>
      <robotBaseFrame>base_link</robotBaseFrame>
    </plugin>
  </gazebo>
  <gazebo reference="base_link">
    <material>Gazebo/Orange</material>
  </gazebo>
  <!-- hokuyo -->
  <gazebo reference="hokuyo_link">
    <sensor name="head_hokuyo_sensor" type="gpu_ray">
      <pose>0 0 0 0 0 0</pose>
      <visualize>false</visualize>
      <update_rate>40</update_rate>
      <ray>
        <scan>
          <horizontal>
            <samples>720</samples>
            <resolution>1</resolution>
            <min_angle>-1.570796</min_angle>
            <max_angle>1.570796</max_angle>
          </horizontal>
        </scan>
        <range>
          <min>0.10</min>
          <max>30.0</max>
          <resolution>0.01</resolution>
        </range>
        <noise>
          <type>gaussian</type>
          <!-- Noise parameters based on published spec for Hokuyo laser
               achieving "+-30mm" accuracy at range < 10m.  A mean of 0.0m and
               stddev of 0.01m will put 99.7% of samples within 0.03m of the true
               reading. -->
          <mean>0.0</mean>
          <stddev>0.01</stddev>
        </noise>
      </ray>
      <plugin filename="libgazebo_ros_gpu_laser.so" name="gazebo_ros_head_hokuyo_controller">
        <topicName>scan</topicName>
        <frameName>hokuyo_link</frameName>
      </plugin>
    </sensor>
  </gazebo>
  <material name="black">
    <color rgba="0.0 0.0 0.0 1.0"/>
  </material>
  <material name="blue">
    <color rgba="0.0 0.0 0.8 1.0"/>
  </material>
  <material name="green">
    <color rgba="0.0 0.8 0.0 1.0"/>
  </material>
  <material name="grey">
    <color rgba="0.2 0.2 0.2 1.0"/>
  </material>
  <material name="orange">
    <color rgba="1.0 0.423529411765 0.0392156862745 1.0"/>
  </material>
  <material name="brown">
    <color rgba="0.870588235294 0.811764705882 0.764705882353 1.0"/>
  </material>
  <material name="red">
    <color rgba="0.8 0.0 0.0 1.0"/>
  </material>
  <material name="white">
    <color rgba="1.0 1.0 1.0 1.0"/>
  </material>
  <!--macro name="cylinder_inertia" params="m r h">
    <inertia  ixx="${m*(3*r*r+h*h)/12}" ixy = "0" ixz = "0"
      iyy="${m*(3*r*r+h*h)/12}" iyz = "0"
      izz="${m*r*r/2}"
    />
  </macro>

  <macro name="box_inertia" params="m x y z">
    <inertia  ixx="${m*(y*y+z*z)/12}" ixy = "0" ixz = "0"
      iyy="${m*(x*x+z*z)/12}" iyz = "0"
      izz="${m*(x*x+z*z)/12}"
    />
  </macro>

  <macro name="sphere_inertia" params="m r">
    <inertia  ixx="${2*m*r*r/5}" ixy = "0" ixz = "0"
      iyy="${2*m*r*r/5}" iyz = "0"
      izz="${2*m*r*r/5}"
    />
  </macro>







  <macro name="wheel" params="lr tY">

    <link name="${lr}_wheel">
      <collision>
        <origin xyz="0 0 0" rpy="0 ${PI/2} ${PI/2}" />
        <geometry>
          <cylinder length="${wheelWidth}" radius="${wheelRadius}"/>
        </geometry>
      </collision>

      <visual>
        <origin xyz="0 0 0" rpy="0 ${PI/2} ${PI/2}" />
        <geometry>
          <cylinder length="${wheelWidth}" radius="${wheelRadius}"/>
        </geometry>
        <material name="black"/>
      </visual>

      <inertial>
        <origin xyz="0 0 0" rpy="0 ${PI/2} ${PI/2}" />
        <mass value="${wheelMass}"/>
        <cylinder_inertia m="${wheelMass}" r="${wheelRadius}" h="${wheelWidth}"/>
      </inertial>
    </link>

    <gazebo reference="${lr}_wheel">
      <mu1 value="1.0"/>
      <mu2 value="1.0"/>
      <kp  value="10000000.0" />
      <kd  value="1.0" />
      <fdir1 value="1 0 0"/>
      <material>Gazebo/Black</material>
    </gazebo>


    <joint name="${lr}_wheel_hinge" type="continuous">
      <parent link="chassis"/>
      <child link="${lr}_wheel"/>
    <origin xyz="${-wheelPos+chassisLength/2} ${tY*wheelWidth/2+tY*chassisWidth/2} ${wheelRadius}" rpy="0 0 0" />
      <axis xyz="0 1 0" rpy="0 0 0" />
      <limit effort="10000" velocity="10000"/>
      <joint_properties damping="0.0" friction="0.0"/>
    </joint>


    <transmission name="${lr}_trans">
      <type>transmission_interface/SimpleTransmission</type>
      <joint name="${lr}_wheel_hinge">
        <hardwareInterface>EffortJointInterface</hardwareInterface>
      </joint>
      <actuator name="${lr}Motor">
        <hardwareInterface>EffortJointInterface</hardwareInterface>
        <mechanicalReduction>10</mechanicalReduction>
      </actuator>
    </transmission>

  </macro-->
  <link name="base_link">
    <pose>0 0 0.1 0 0 0</pose>
    <inertial>
      <mass value="10.0"/>
      <origin rpy=" 0 0 0" xyz="0.0 0 0.1"/>
      <inertia ixx="0.5" ixy="0" ixz="0" iyy="1.0" iyz="0" izz="0.1"/>
    </inertial>
    <collision name="collision">
      <geometry>
        <box size=".4 .2 .1"/>
      </geometry>
    </collision>
    <visual name="chassis_visual">
      <origin rpy=" 0 0 0" xyz="0 0 0"/>
      <geometry>
        <box size=".4 .2 .1"/>
      </geometry>
    </visual>
    <collision name="caster_collision">
      <origin rpy=" 0 0 0" xyz="-0.15 0 -0.05"/>
      <geometry>
        <sphere radius="0.05"/>
      </geometry>
      <surface>
        <friction>
          <ode>
            <mu>0</mu>
            <mu2>0</mu2>
            <slip1>1.0</slip1>
            <slip2>1.0</slip2>
          </ode>
        </friction>
      </surface>
    </collision>
    <visual name="caster_visual">
      <origin rpy=" 0 0 0" xyz="-0.15 0 -0.05"/>
      <geometry>
        <sphere radius="0.05"/>
      </geometry>
    </visual>
  </link>
  <link name="left_wheel">
    <!--origin xyz="0.1 0.13 0.1" rpy="0 1.5707 1.5707"/-->
    <collision name="collision">
      <origin rpy="0 1.5707 1.5707" xyz="0 0 0"/>
      <geometry>
        <cylinder length="0.05" radius="0.1"/>
      </geometry>
    </collision>
    <visual name="left_wheel_visual">
      <origin rpy="0 1.5707 1.5707" xyz="0 0 0"/>
      <geometry>
        <cylinder length="0.05" radius="0.1"/>
      </geometry>
    </visual>
    <inertial>
      <origin rpy="0 1.5707 1.5707" xyz="0 0 0"/>
      <mass value="5"/>
      <cylinder_inertia h="0.05" m="5" r="0.1"/>
      <inertia ixx="1.0" ixy="0.0" ixz="0.0" iyy="1.0" iyz="0.0" izz="1.0"/>
    </inertial>
  </link>
  <link name="right_wheel">
    <!--origin xyz="0.1 -0.13 0.1" rpy="0 1.5707 1.5707"/-->
    <collision name="collision">
      <origin rpy="0 1.5707 1.5707" xyz="0 0 0"/>
      <geometry>
        <cylinder length="0.05" radius="0.1"/>
      </geometry>
    </collision>
    <visual name="right_wheel_visual">
      <origin rpy="0 1.5707 1.5707" xyz="0 0 0"/>
      <geometry>
        <cylinder length="0.05" radius="0.1"/>
      </geometry>
    </visual>
    <inertial>
      <origin rpy="0 1.5707 1.5707" xyz="0 0 0"/>
      <mass value="5"/>
      <cylinder_inertia h="0.05" m="5" r="0.1"/>
      <inertia ixx="1.0" ixy="0.0" ixz="0.0" iyy="1.0" iyz="0.0" izz="1.0"/>
    </inertial>
  </link>
  <joint name="left_wheel_hinge" type="continuous">
    <origin rpy="0 0 0" xyz="0.1 0.15 0"/>
    <child link="left_wheel"/>
    <parent link="base_link"/>
    <axis rpy="0 0 0" xyz="0 1 0"/>
    <limit effort="100" velocity="100"/>
    <joint_properties damping="0.0" friction="0.0"/>
  </joint>
  <joint name="right_wheel_hinge" type="continuous">
    <origin rpy="0 0 0" xyz="0.1 -0.15 0"/>
    <child link="right_wheel"/>
    <parent link="base_link"/>
    <axis rpy="0 0 0" xyz="0 1 0"/>
    <limit effort="100" velocity="100"/>
    <joint_properties damping="0.0" friction="0.0"/>
  </joint>
  <!-- Hokuyo Laser -->
  <joint name="hokuyo_joint" type="fixed">
    <axis xyz="0 1 0"/>
    <origin rpy="0 0 0" xyz="0 0 0"/>
    <parent link="base_link"/>
    <child link="hokuyo_link"/>
  </joint>
  <link name="hokuyo_link">
    <collision>
      <origin rpy="0 0 0" xyz="0 0 0"/>
      <geometry>
        <box size="0.1 0.1 0.1"/>
      </geometry>
    </collision>
    <visual>
      <origin rpy="0 0 0" xyz="0 0 0.08"/>
      <geometry>
        <mesh filename="package://myrobot_description/hokuyo/meshes/hokuyo.dae"/>
      </geometry>
    </visual>
    <inertial>
      <mass value="1e-5"/>
      <origin rpy="0 0 0" xyz="0 0 0"/>
      <inertia ixx="1e-6" ixy="0" ixz="0" iyy="1e-6" iyz="0" izz="1e-6"/>
    </inertial>
  </link>
</robot>

